<?xml version="1.0" ?>
<mujoco model="vrm_physics_body">
    <compiler angle="radian" meshdir="STL" autolimits="true"/>
    <default>
        <geom density="1000" contype="1" conaffinity="0"/>
        <joint damping="0.01" stiffness="0.0"/>
    </default>
    <asset>
        <mesh name="J_Bip_C_Hips" file="J_Bip_C_Hips.stl"/>
        <mesh name="J_Bip_C_Spine" file="J_Bip_C_Spine.stl"/>
        <mesh name="J_Bip_C_Chest" file="J_Bip_C_Chest.stl"/>
        <mesh name="J_Bip_C_UpperChest" file="J_Bip_C_UpperChest.stl"/>
        <mesh name="J_Sec_L_Bust1" file="J_Sec_L_Bust1.stl"/>
        <mesh name="J_Sec_R_Bust1" file="J_Sec_R_Bust1.stl"/>
        <mesh name="J_Bip_C_Neck" file="J_Bip_C_Neck.stl"/>
        <mesh name="J_Bip_C_Head" file="J_Bip_C_Head.stl"/>
        <mesh name="J_Bip_L_Shoulder" file="J_Bip_L_Shoulder.stl"/>
        <mesh name="J_Bip_L_UpperArm" file="J_Bip_L_UpperArm.stl"/>
        <mesh name="J_Bip_L_LowerArm" file="J_Bip_L_LowerArm.stl"/>
        <mesh name="J_Bip_L_Hand" file="J_Bip_L_Hand.stl"/>
        <mesh name="J_Bip_L_Index1" file="J_Bip_L_Index1.stl"/>
        <mesh name="J_Bip_L_Index2" file="J_Bip_L_Index2.stl"/>
        <mesh name="J_Bip_L_Index3" file="J_Bip_L_Index3.stl"/>
        <mesh name="J_Bip_L_Little1" file="J_Bip_L_Little1.stl"/>
        <mesh name="J_Bip_L_Little2" file="J_Bip_L_Little2.stl"/>
        <mesh name="J_Bip_L_Little3" file="J_Bip_L_Little3.stl"/>
        <mesh name="J_Bip_L_Middle1" file="J_Bip_L_Middle1.stl"/>
        <mesh name="J_Bip_L_Middle2" file="J_Bip_L_Middle2.stl"/>
        <mesh name="J_Bip_L_Middle3" file="J_Bip_L_Middle3.stl"/>
        <mesh name="J_Bip_L_Ring1" file="J_Bip_L_Ring1.stl"/>
        <mesh name="J_Bip_L_Ring2" file="J_Bip_L_Ring2.stl"/>
        <mesh name="J_Bip_L_Ring3" file="J_Bip_L_Ring3.stl"/>
        <mesh name="J_Bip_L_Thumb1" file="J_Bip_L_Thumb1.stl"/>
        <mesh name="J_Bip_L_Thumb2" file="J_Bip_L_Thumb2.stl"/>
        <mesh name="J_Bip_L_Thumb3" file="J_Bip_L_Thumb3.stl"/>
        <mesh name="J_Bip_R_Shoulder" file="J_Bip_R_Shoulder.stl"/>
        <mesh name="J_Bip_R_UpperArm" file="J_Bip_R_UpperArm.stl"/>
        <mesh name="J_Bip_R_LowerArm" file="J_Bip_R_LowerArm.stl"/>
        <mesh name="J_Bip_R_Hand" file="J_Bip_R_Hand.stl"/>
        <mesh name="J_Bip_R_Index1" file="J_Bip_R_Index1.stl"/>
        <mesh name="J_Bip_R_Index2" file="J_Bip_R_Index2.stl"/>
        <mesh name="J_Bip_R_Index3" file="J_Bip_R_Index3.stl"/>
        <mesh name="J_Bip_R_Little1" file="J_Bip_R_Little1.stl"/>
        <mesh name="J_Bip_R_Little2" file="J_Bip_R_Little2.stl"/>
        <mesh name="J_Bip_R_Little3" file="J_Bip_R_Little3.stl"/>
        <mesh name="J_Bip_R_Middle1" file="J_Bip_R_Middle1.stl"/>
        <mesh name="J_Bip_R_Middle2" file="J_Bip_R_Middle2.stl"/>
        <mesh name="J_Bip_R_Middle3" file="J_Bip_R_Middle3.stl"/>
        <mesh name="J_Bip_R_Ring1" file="J_Bip_R_Ring1.stl"/>
        <mesh name="J_Bip_R_Ring2" file="J_Bip_R_Ring2.stl"/>
        <mesh name="J_Bip_R_Ring3" file="J_Bip_R_Ring3.stl"/>
        <mesh name="J_Bip_R_Thumb1" file="J_Bip_R_Thumb1.stl"/>
        <mesh name="J_Bip_R_Thumb2" file="J_Bip_R_Thumb2.stl"/>
        <mesh name="J_Bip_R_Thumb3" file="J_Bip_R_Thumb3.stl"/>
        <mesh name="J_Bip_L_UpperLeg" file="J_Bip_L_UpperLeg.stl"/>
        <mesh name="J_Bip_L_LowerLeg" file="J_Bip_L_LowerLeg.stl"/>
        <mesh name="J_Bip_L_Foot" file="J_Bip_L_Foot.stl"/>
        <mesh name="J_Bip_L_ToeBase" file="J_Bip_L_ToeBase.stl"/>
        <mesh name="J_Bip_R_UpperLeg" file="J_Bip_R_UpperLeg.stl"/>
        <mesh name="J_Bip_R_LowerLeg" file="J_Bip_R_LowerLeg.stl"/>
        <mesh name="J_Bip_R_Foot" file="J_Bip_R_Foot.stl"/>
        <mesh name="J_Bip_R_ToeBase" file="J_Bip_R_ToeBase.stl"/>
    </asset>
    <worldbody>
        <geom type="plane" size="5 5 0.1" name="floor" zaxis="0 1 0" contype="0" conaffinity="1"/>
        <body name="J_Bip_C_Hips" pos="0.000000 1.109305 0.000000">
            <freejoint name="root_freejoint"/>
            <geom type="mesh" mesh="J_Bip_C_Hips"/>
            <geom type="sphere" size="0.05" mass="0.5" contype="0" conaffinity="0" rgba="0 0 0 0"/>
            <body name="J_Bip_C_Spine" pos="-0.000000 0.057098 0.005326">
                <joint name="J_Bip_C_Spine" type="ball"/>
                <geom type="mesh" mesh="J_Bip_C_Spine"/>
                <geom type="sphere" size="0.05" mass="0.5" contype="0" conaffinity="0" rgba="0 0 0 0"/>
                <body name="J_Bip_C_Chest" pos="0.000000 0.106512 -0.012713">
                    <joint name="J_Bip_C_Chest" type="ball"/>
                    <geom type="mesh" mesh="J_Bip_C_Chest"/>
                    <geom type="sphere" size="0.05" mass="0.5" contype="0" conaffinity="0" rgba="0 0 0 0"/>
                    <body name="J_Bip_C_UpperChest" pos="-0.000000 0.102391 -0.001320">
                        <joint name="J_Bip_C_UpperChest" type="ball"/>
                        <geom type="mesh" mesh="J_Bip_C_UpperChest"/>
                        <geom type="sphere" size="0.05" mass="0.5" contype="0" conaffinity="0" rgba="0 0 0 0"/>
                        <body name="J_Sec_L_Bust1" pos="0.045813 -0.026929 0.056758">
                            <joint name="J_Sec_L_Bust1" type="ball"/>
                            <geom type="mesh" mesh="J_Sec_L_Bust1"/>
                            <geom type="sphere" size="0.05" mass="0.5" contype="0" conaffinity="0" rgba="0 0 0 0"/>
                            <body name="J_Sec_L_Bust2" pos="-0.001044 0.000069 0.043307">
                                <joint name="J_Sec_L_Bust2" type="ball"/>
                                <geom type="sphere" size="0.05" mass="0.5" contype="0" conaffinity="0" rgba="0 0 0 0"/>
                            </body>
                        </body>
                        <body name="J_Sec_R_Bust1" pos="-0.045813 -0.026929 0.056758">
                            <joint name="J_Sec_R_Bust1" type="ball"/>
                            <geom type="mesh" mesh="J_Sec_R_Bust1"/>
                            <geom type="sphere" size="0.05" mass="0.5" contype="0" conaffinity="0" rgba="0 0 0 0"/>
                            <body name="J_Sec_R_Bust2" pos="0.001044 0.000069 0.043307">
                                <joint name="J_Sec_R_Bust2" type="ball"/>
                                <geom type="sphere" size="0.05" mass="0.5" contype="0" conaffinity="0" rgba="0 0 0 0"/>
                            </body>
                        </body>
                        <body name="J_Bip_C_Neck" pos="-0.000000 0.124557 0.006980">
                            <joint name="J_Bip_C_Neck" type="ball"/>
                            <geom type="mesh" mesh="J_Bip_C_Neck"/>
                            <geom type="sphere" size="0.05" mass="0.5" contype="0" conaffinity="0" rgba="0 0 0 0"/>
                            <body name="J_Bip_C_Head" pos="-0.000000 0.071787 0.000372">
                                <joint name="J_Bip_C_Head" type="ball"/>
                                <geom type="mesh" mesh="J_Bip_C_Head"/>
                                <geom type="sphere" size="0.05" mass="0.5" contype="0" conaffinity="0" rgba="0 0 0 0"/>
                                <body name="J_Adj_L_FaceEye" pos="0.014650 0.063260 0.023188">
                                    <joint name="J_Adj_L_FaceEye" type="ball"/>
                                    <geom type="sphere" size="0.05" mass="0.5" contype="0" conaffinity="0" rgba="0 0 0 0"/>
                                </body>
                                <body name="J_Adj_R_FaceEye" pos="-0.014650 0.063260 0.023188">
                                    <joint name="J_Adj_R_FaceEye" type="ball"/>
                                    <geom type="sphere" size="0.05" mass="0.5" contype="0" conaffinity="0" rgba="0 0 0 0"/>
                                </body>
                                <body name="J_Sec_Hair1_01" pos="0.002419 0.108442 0.107708">
                                    <joint name="J_Sec_Hair1_01" type="ball"/>
                                    <geom type="sphere" size="0.05" mass="0.5" contype="0" conaffinity="0" rgba="0 0 0 0"/>
                                    <body name="J_Sec_Hair2_01" pos="0.001229 0.052552 -0.000000">
                                        <joint name="J_Sec_Hair2_01" type="ball"/>
                                        <geom type="sphere" size="0.05" mass="0.5" contype="0" conaffinity="0" rgba="0 0 0 0"/>
                                    </body>
                                </body>
                                <body name="J_Sec_Hair1_02" pos="0.069055 0.072728 0.090523">
                                    <joint name="J_Sec_Hair1_02" type="ball"/>
                                    <geom type="sphere" size="0.05" mass="0.5" contype="0" conaffinity="0" rgba="0 0 0 0"/>
                                    <body name="J_Sec_Hair2_02" pos="-0.000484 0.066251 0.000000">
                                        <joint name="J_Sec_Hair2_02" type="ball"/>
                                        <geom type="sphere" size="0.05" mass="0.5" contype="0" conaffinity="0" rgba="0 0 0 0"/>
                                        <body name="J_Sec_Hair3_02" pos="-0.002515 0.062720 -0.000000">
                                            <joint name="J_Sec_Hair3_02" type="ball"/>
                                            <geom type="sphere" size="0.05" mass="0.5" contype="0" conaffinity="0" rgba="0 0 0 0"/>
                                        </body>
                                    </body>
                                </body>
                                <body name="J_Sec_Hair1_03" pos="0.086742 0.076004 0.003153">
                                    <joint name="J_Sec_Hair1_03" type="ball"/>
                                    <geom type="sphere" size="0.05" mass="0.5" contype="0" conaffinity="0" rgba="0 0 0 0"/>
                                    <body name="J_Sec_Hair2_03" pos="0.000127 0.044013 -0.000000">
                                        <joint name="J_Sec_Hair2_03" type="ball"/>
                                        <geom type="sphere" size="0.05" mass="0.5" contype="0" conaffinity="0" rgba="0 0 0 0"/>
                                        <body name="J_Sec_Hair3_03" pos="0.000271 0.043324 0.000000">
                                            <joint name="J_Sec_Hair3_03" type="ball"/>
                                            <geom type="sphere" size="0.05" mass="0.5" contype="0" conaffinity="0" rgba="0 0 0 0"/>
                                            <body name="J_Sec_Hair4_03" pos="-0.002194 0.040856 -0.000000">
                                                <joint name="J_Sec_Hair4_03" type="ball"/>
                                                <geom type="sphere" size="0.05" mass="0.5" contype="0" conaffinity="0" rgba="0 0 0 0"/>
                                            </body>
                                        </body>
                                    </body>
                                </body>
                                <body name="J_Sec_Hair1_04" pos="0.087952 0.082531 -0.034798">
                                    <joint name="J_Sec_Hair1_04" type="ball"/>
                                    <geom type="sphere" size="0.05" mass="0.5" contype="0" conaffinity="0" rgba="0 0 0 0"/>
                                    <body name="J_Sec_Hair2_04" pos="-0.000263 0.045137 -0.000000">
                                        <joint name="J_Sec_Hair2_04" type="ball"/>
                                        <geom type="sphere" size="0.05" mass="0.5" contype="0" conaffinity="0" rgba="0 0 0 0"/>
                                        <body name="J_Sec_Hair3_04" pos="0.000365 0.045153 -0.000000">
                                            <joint name="J_Sec_Hair3_04" type="ball"/>
                                            <geom type="sphere" size="0.05" mass="0.5" contype="0" conaffinity="0" rgba="0 0 0 0"/>
                                            <body name="J_Sec_Hair4_04" pos="-0.001400 0.040048 0.000000">
                                                <joint name="J_Sec_Hair4_04" type="ball"/>
                                                <geom type="sphere" size="0.05" mass="0.5" contype="0" conaffinity="0" rgba="0 0 0 0"/>
                                            </body>
                                        </body>
                                    </body>
                                </body>
                                <body name="J_Sec_Hair1_05" pos="-0.074234 0.099107 0.078419">
                                    <joint name="J_Sec_Hair1_05" type="ball"/>
                                    <geom type="sphere" size="0.05" mass="0.5" contype="0" conaffinity="0" rgba="0 0 0 0"/>
                                    <body name="J_Sec_Hair2_05" pos="-0.000331 0.074893 0.000000">
                                        <joint name="J_Sec_Hair2_05" type="ball"/>
                                        <geom type="sphere" size="0.05" mass="0.5" contype="0" conaffinity="0" rgba="0 0 0 0"/>
                                        <body name="J_Sec_Hair3_05" pos="0.002255 0.072153 0.000000">
                                            <joint name="J_Sec_Hair3_05" type="ball"/>
                                            <geom type="sphere" size="0.05" mass="0.5" contype="0" conaffinity="0" rgba="0 0 0 0"/>
                                        </body>
                                    </body>
                                </body>
                                <body name="J_Sec_Hair1_06" pos="0.000381 0.090281 -0.119759">
                                    <joint name="J_Sec_Hair1_06" type="ball"/>
                                    <geom type="sphere" size="0.05" mass="0.5" contype="0" conaffinity="0" rgba="0 0 0 0"/>
                                    <body name="J_Sec_Hair2_06" pos="-0.000280 0.042569 0.000000">
                                        <joint name="J_Sec_Hair2_06" type="ball"/>
                                        <geom type="sphere" size="0.05" mass="0.5" contype="0" conaffinity="0" rgba="0 0 0 0"/>
                                        <body name="J_Sec_Hair3_06" pos="-0.000558 0.042443 0.000000">
                                            <joint name="J_Sec_Hair3_06" type="ball"/>
                                            <geom type="sphere" size="0.05" mass="0.5" contype="0" conaffinity="0" rgba="0 0 0 0"/>
                                            <body name="J_Sec_Hair4_06" pos="0.000391 0.042381 -0.000000">
                                                <joint name="J_Sec_Hair4_06" type="ball"/>
                                                <geom type="sphere" size="0.05" mass="0.5" contype="0" conaffinity="0" rgba="0 0 0 0"/>
                                            </body>
                                        </body>
                                    </body>
                                </body>
                                <body name="J_Sec_Hair1_07" pos="-0.092210 0.087500 -0.000829">
                                    <joint name="J_Sec_Hair1_07" type="ball"/>
                                    <geom type="sphere" size="0.05" mass="0.5" contype="0" conaffinity="0" rgba="0 0 0 0"/>
                                    <body name="J_Sec_Hair2_07" pos="-0.000233 0.043964 -0.000000">
                                        <joint name="J_Sec_Hair2_07" type="ball"/>
                                        <geom type="sphere" size="0.05" mass="0.5" contype="0" conaffinity="0" rgba="0 0 0 0"/>
                                        <body name="J_Sec_Hair3_07" pos="-0.000981 0.043719 -0.000000">
                                            <joint name="J_Sec_Hair3_07" type="ball"/>
                                            <geom type="sphere" size="0.05" mass="0.5" contype="0" conaffinity="0" rgba="0 0 0 0"/>
                                            <body name="J_Sec_Hair4_07" pos="0.000891 0.041266 -0.000000">
                                                <joint name="J_Sec_Hair4_07" type="ball"/>
                                                <geom type="sphere" size="0.05" mass="0.5" contype="0" conaffinity="0" rgba="0 0 0 0"/>
                                            </body>
                                        </body>
                                    </body>
                                </body>
                            </body>
                        </body>
                        <body name="J_Bip_L_Shoulder" pos="0.020164 0.099307 0.006153">
                            <joint name="J_Bip_L_Shoulder" type="ball"/>
                            <geom type="mesh" mesh="J_Bip_L_Shoulder"/>
                            <geom type="sphere" size="0.05" mass="0.5" contype="0" conaffinity="0" rgba="0 0 0 0"/>
                            <body name="J_Bip_L_UpperArm" pos="0.060882 -0.000051 -0.000000">
                                <joint name="J_Bip_L_UpperArm" type="ball"/>
                                <geom type="mesh" mesh="J_Bip_L_UpperArm"/>
                                <geom type="sphere" size="0.05" mass="0.5" contype="0" conaffinity="0" rgba="0 0 0 0"/>
                                <body name="J_Bip_L_LowerArm" pos="0.253601 0.000000 0.000000">
                                    <joint name="J_Bip_L_LowerArm" type="ball"/>
                                    <geom type="mesh" mesh="J_Bip_L_LowerArm"/>
                                    <geom type="sphere" size="0.05" mass="0.5" contype="0" conaffinity="0" rgba="0 0 0 0"/>
                                    <body name="J_Bip_L_Hand" pos="0.226637 -0.000000 0.000014">
                                        <joint name="J_Bip_L_Hand" type="ball"/>
                                        <geom type="mesh" mesh="J_Bip_L_Hand"/>
                                        <geom type="sphere" size="0.05" mass="0.5" contype="0" conaffinity="0" rgba="0 0 0 0"/>
                                        <body name="J_Bip_L_Index1" pos="0.054373 0.006165 0.016419">
                                            <joint name="J_Bip_L_Index1" type="ball"/>
                                            <geom type="mesh" mesh="J_Bip_L_Index1"/>
                                            <geom type="sphere" size="0.05" mass="0.5" contype="0" conaffinity="0" rgba="0 0 0 0"/>
                                            <body name="J_Bip_L_Index2" pos="0.027624 0.000000 -0.000004">
                                                <joint name="J_Bip_L_Index2" type="ball"/>
                                                <geom type="mesh" mesh="J_Bip_L_Index2"/>
                                                <geom type="sphere" size="0.05" mass="0.5" contype="0" conaffinity="0" rgba="0 0 0 0"/>
                                                <body name="J_Bip_L_Index3" pos="0.017008 -0.000003 -0.000004">
                                                    <joint name="J_Bip_L_Index3" type="ball"/>
                                                    <geom type="mesh" mesh="J_Bip_L_Index3"/>
                                                    <geom type="sphere" size="0.05" mass="0.5" contype="0" conaffinity="0" rgba="0 0 0 0"/>
                                                </body>
                                            </body>
                                        </body>
                                        <body name="J_Bip_L_Little1" pos="0.050734 0.006165 -0.024370">
                                            <joint name="J_Bip_L_Little1" type="ball"/>
                                            <geom type="mesh" mesh="J_Bip_L_Little1"/>
                                            <geom type="sphere" size="0.05" mass="0.5" contype="0" conaffinity="0" rgba="0 0 0 0"/>
                                            <body name="J_Bip_L_Little2" pos="0.026108 0.000000 0.000000">
                                                <joint name="J_Bip_L_Little2" type="ball"/>
                                                <geom type="mesh" mesh="J_Bip_L_Little2"/>
                                                <geom type="sphere" size="0.05" mass="0.5" contype="0" conaffinity="0" rgba="0 0 0 0"/>
                                                <body name="J_Bip_L_Little3" pos="0.015047 0.000000 0.000000">
                                                    <joint name="J_Bip_L_Little3" type="ball"/>
                                                    <geom type="mesh" mesh="J_Bip_L_Little3"/>
                                                    <geom type="sphere" size="0.05" mass="0.5" contype="0" conaffinity="0" rgba="0 0 0 0"/>
                                                </body>
                                            </body>
                                        </body>
                                        <body name="J_Bip_L_Middle1" pos="0.055114 0.006165 0.001710">
                                            <joint name="J_Bip_L_Middle1" type="ball"/>
                                            <geom type="mesh" mesh="J_Bip_L_Middle1"/>
                                            <geom type="sphere" size="0.05" mass="0.5" contype="0" conaffinity="0" rgba="0 0 0 0"/>
                                            <body name="J_Bip_L_Middle2" pos="0.030770 -0.000000 -0.000000">
                                                <joint name="J_Bip_L_Middle2" type="ball"/>
                                                <geom type="mesh" mesh="J_Bip_L_Middle2"/>
                                                <geom type="sphere" size="0.05" mass="0.5" contype="0" conaffinity="0" rgba="0 0 0 0"/>
                                                <body name="J_Bip_L_Middle3" pos="0.018983 0.000000 -0.000000">
                                                    <joint name="J_Bip_L_Middle3" type="ball"/>
                                                    <geom type="mesh" mesh="J_Bip_L_Middle3"/>
                                                    <geom type="sphere" size="0.05" mass="0.5" contype="0" conaffinity="0" rgba="0 0 0 0"/>
                                                </body>
                                            </body>
                                        </body>
                                        <body name="J_Bip_L_Ring1" pos="0.054486 0.006165 -0.011350">
                                            <joint name="J_Bip_L_Ring1" type="ball"/>
                                            <geom type="mesh" mesh="J_Bip_L_Ring1"/>
                                            <geom type="sphere" size="0.05" mass="0.5" contype="0" conaffinity="0" rgba="0 0 0 0"/>
                                            <body name="J_Bip_L_Ring2" pos="0.028543 0.000000 0.000000">
                                                <joint name="J_Bip_L_Ring2" type="ball"/>
                                                <geom type="mesh" mesh="J_Bip_L_Ring2"/>
                                                <geom type="sphere" size="0.05" mass="0.5" contype="0" conaffinity="0" rgba="0 0 0 0"/>
                                                <body name="J_Bip_L_Ring3" pos="0.016472 0.000000 0.000000">
                                                    <joint name="J_Bip_L_Ring3" type="ball"/>
                                                    <geom type="mesh" mesh="J_Bip_L_Ring3"/>
                                                    <geom type="sphere" size="0.05" mass="0.5" contype="0" conaffinity="0" rgba="0 0 0 0"/>
                                                </body>
                                            </body>
                                        </body>
                                        <body name="J_Bip_L_Thumb1" pos="0.002926 -0.008360 0.013334">
                                            <joint name="J_Bip_L_Thumb1" type="ball"/>
                                            <geom type="mesh" mesh="J_Bip_L_Thumb1"/>
                                            <geom type="sphere" size="0.05" mass="0.5" contype="0" conaffinity="0" rgba="0 0 0 0"/>
                                            <body name="J_Bip_L_Thumb2" pos="0.038790 0.000114 -0.000006">
                                                <joint name="J_Bip_L_Thumb2" type="ball"/>
                                                <geom type="mesh" mesh="J_Bip_L_Thumb2"/>
                                                <geom type="sphere" size="0.05" mass="0.5" contype="0" conaffinity="0" rgba="0 0 0 0"/>
                                                <body name="J_Bip_L_Thumb3" pos="0.023854 0.000069 -0.000005">
                                                    <joint name="J_Bip_L_Thumb3" type="ball"/>
                                                    <geom type="mesh" mesh="J_Bip_L_Thumb3"/>
                                                    <geom type="sphere" size="0.05" mass="0.5" contype="0" conaffinity="0" rgba="0 0 0 0"/>
                                                </body>
                                            </body>
                                        </body>
                                    </body>
                                </body>
                            </body>
                        </body>
                        <body name="J_Bip_R_Shoulder" pos="-0.020164 0.099307 0.006153">
                            <joint name="J_Bip_R_Shoulder" type="ball"/>
                            <geom type="mesh" mesh="J_Bip_R_Shoulder"/>
                            <geom type="sphere" size="0.05" mass="0.5" contype="0" conaffinity="0" rgba="0 0 0 0"/>
                            <body name="J_Bip_R_UpperArm" pos="-0.060882 -0.000051 -0.000000">
                                <joint name="J_Bip_R_UpperArm" type="ball"/>
                                <geom type="mesh" mesh="J_Bip_R_UpperArm"/>
                                <geom type="sphere" size="0.05" mass="0.5" contype="0" conaffinity="0" rgba="0 0 0 0"/>
                                <body name="J_Bip_R_LowerArm" pos="-0.253601 0.000000 0.000000">
                                    <joint name="J_Bip_R_LowerArm" type="ball"/>
                                    <geom type="mesh" mesh="J_Bip_R_LowerArm"/>
                                    <geom type="sphere" size="0.05" mass="0.5" contype="0" conaffinity="0" rgba="0 0 0 0"/>
                                    <body name="J_Bip_R_Hand" pos="-0.226637 -0.000000 0.000014">
                                        <joint name="J_Bip_R_Hand" type="ball"/>
                                        <geom type="mesh" mesh="J_Bip_R_Hand"/>
                                        <geom type="sphere" size="0.05" mass="0.5" contype="0" conaffinity="0" rgba="0 0 0 0"/>
                                        <body name="J_Bip_R_Index1" pos="-0.054373 0.006165 0.016419">
                                            <joint name="J_Bip_R_Index1" type="ball"/>
                                            <geom type="mesh" mesh="J_Bip_R_Index1"/>
                                            <geom type="sphere" size="0.05" mass="0.5" contype="0" conaffinity="0" rgba="0 0 0 0"/>
                                            <body name="J_Bip_R_Index2" pos="-0.027624 0.000000 -0.000004">
                                                <joint name="J_Bip_R_Index2" type="ball"/>
                                                <geom type="mesh" mesh="J_Bip_R_Index2"/>
                                                <geom type="sphere" size="0.05" mass="0.5" contype="0" conaffinity="0" rgba="0 0 0 0"/>
                                                <body name="J_Bip_R_Index3" pos="-0.017008 -0.000003 -0.000004">
                                                    <joint name="J_Bip_R_Index3" type="ball"/>
                                                    <geom type="mesh" mesh="J_Bip_R_Index3"/>
                                                    <geom type="sphere" size="0.05" mass="0.5" contype="0" conaffinity="0" rgba="0 0 0 0"/>
                                                </body>
                                            </body>
                                        </body>
                                        <body name="J_Bip_R_Little1" pos="-0.050734 0.006165 -0.024370">
                                            <joint name="J_Bip_R_Little1" type="ball"/>
                                            <geom type="mesh" mesh="J_Bip_R_Little1"/>
                                            <geom type="sphere" size="0.05" mass="0.5" contype="0" conaffinity="0" rgba="0 0 0 0"/>
                                            <body name="J_Bip_R_Little2" pos="-0.026108 0.000000 0.000000">
                                                <joint name="J_Bip_R_Little2" type="ball"/>
                                                <geom type="mesh" mesh="J_Bip_R_Little2"/>
                                                <geom type="sphere" size="0.05" mass="0.5" contype="0" conaffinity="0" rgba="0 0 0 0"/>
                                                <body name="J_Bip_R_Little3" pos="-0.015047 0.000000 0.000000">
                                                    <joint name="J_Bip_R_Little3" type="ball"/>
                                                    <geom type="mesh" mesh="J_Bip_R_Little3"/>
                                                    <geom type="sphere" size="0.05" mass="0.5" contype="0" conaffinity="0" rgba="0 0 0 0"/>
                                                </body>
                                            </body>
                                        </body>
                                        <body name="J_Bip_R_Middle1" pos="-0.055114 0.006165 0.001710">
                                            <joint name="J_Bip_R_Middle1" type="ball"/>
                                            <geom type="mesh" mesh="J_Bip_R_Middle1"/>
                                            <geom type="sphere" size="0.05" mass="0.5" contype="0" conaffinity="0" rgba="0 0 0 0"/>
                                            <body name="J_Bip_R_Middle2" pos="-0.030770 -0.000000 -0.000000">
                                                <joint name="J_Bip_R_Middle2" type="ball"/>
                                                <geom type="mesh" mesh="J_Bip_R_Middle2"/>
                                                <geom type="sphere" size="0.05" mass="0.5" contype="0" conaffinity="0" rgba="0 0 0 0"/>
                                                <body name="J_Bip_R_Middle3" pos="-0.018983 0.000000 -0.000000">
                                                    <joint name="J_Bip_R_Middle3" type="ball"/>
                                                    <geom type="mesh" mesh="J_Bip_R_Middle3"/>
                                                    <geom type="sphere" size="0.05" mass="0.5" contype="0" conaffinity="0" rgba="0 0 0 0"/>
                                                </body>
                                            </body>
                                        </body>
                                        <body name="J_Bip_R_Ring1" pos="-0.054486 0.006165 -0.011350">
                                            <joint name="J_Bip_R_Ring1" type="ball"/>
                                            <geom type="mesh" mesh="J_Bip_R_Ring1"/>
                                            <geom type="sphere" size="0.05" mass="0.5" contype="0" conaffinity="0" rgba="0 0 0 0"/>
                                            <body name="J_Bip_R_Ring2" pos="-0.028543 0.000000 0.000000">
                                                <joint name="J_Bip_R_Ring2" type="ball"/>
                                                <geom type="mesh" mesh="J_Bip_R_Ring2"/>
                                                <geom type="sphere" size="0.05" mass="0.5" contype="0" conaffinity="0" rgba="0 0 0 0"/>
                                                <body name="J_Bip_R_Ring3" pos="-0.016472 0.000000 0.000000">
                                                    <joint name="J_Bip_R_Ring3" type="ball"/>
                                                    <geom type="mesh" mesh="J_Bip_R_Ring3"/>
                                                    <geom type="sphere" size="0.05" mass="0.5" contype="0" conaffinity="0" rgba="0 0 0 0"/>
                                                </body>
                                            </body>
                                        </body>
                                        <body name="J_Bip_R_Thumb1" pos="-0.002926 -0.008360 0.013334">
                                            <joint name="J_Bip_R_Thumb1" type="ball"/>
                                            <geom type="mesh" mesh="J_Bip_R_Thumb1"/>
                                            <geom type="sphere" size="0.05" mass="0.5" contype="0" conaffinity="0" rgba="0 0 0 0"/>
                                            <body name="J_Bip_R_Thumb2" pos="-0.038790 0.000114 -0.000006">
                                                <joint name="J_Bip_R_Thumb2" type="ball"/>
                                                <geom type="mesh" mesh="J_Bip_R_Thumb2"/>
                                                <geom type="sphere" size="0.05" mass="0.5" contype="0" conaffinity="0" rgba="0 0 0 0"/>
                                                <body name="J_Bip_R_Thumb3" pos="-0.023854 0.000069 -0.000005">
                                                    <joint name="J_Bip_R_Thumb3" type="ball"/>
                                                    <geom type="mesh" mesh="J_Bip_R_Thumb3"/>
                                                    <geom type="sphere" size="0.05" mass="0.5" contype="0" conaffinity="0" rgba="0 0 0 0"/>
                                                </body>
                                            </body>
                                        </body>
                                    </body>
                                </body>
                            </body>
                        </body>
                    </body>
                </body>
            </body>
            <body name="J_Bip_L_UpperLeg" pos="0.069469 -0.036155 0.001237">
                <joint name="J_Bip_L_UpperLeg" type="ball"/>
                <geom type="mesh" mesh="J_Bip_L_UpperLeg"/>
                <geom type="sphere" size="0.05" mass="0.5" contype="0" conaffinity="0" rgba="0 0 0 0"/>
                <body name="J_Bip_L_LowerLeg" pos="-0.000000 -0.364862 -0.000001">
                    <joint name="J_Bip_L_LowerLeg" type="ball"/>
                    <geom type="mesh" mesh="J_Bip_L_LowerLeg"/>
                    <geom type="sphere" size="0.05" mass="0.5" contype="0" conaffinity="0" rgba="0 0 0 0"/>
                    <body name="J_Bip_L_Foot" pos="-0.000111 -0.409190 0.002444">
                        <joint name="J_Bip_L_Foot" type="ball"/>
                        <geom type="mesh" mesh="J_Bip_L_Foot"/>
                        <geom type="sphere" size="0.05" mass="0.5" contype="0" conaffinity="0" rgba="0 0 0 0"/>
                        <body name="J_Bip_L_ToeBase" pos="0.000000 -0.053395 0.094937">
                            <joint name="J_Bip_L_ToeBase" type="ball"/>
                            <geom type="mesh" mesh="J_Bip_L_ToeBase"/>
                            <geom type="sphere" size="0.05" mass="0.5" contype="0" conaffinity="0" rgba="0 0 0 0"/>
                        </body>
                    </body>
                </body>
            </body>
            <body name="J_Bip_R_UpperLeg" pos="-0.069469 -0.036155 0.001237">
                <joint name="J_Bip_R_UpperLeg" type="ball"/>
                <geom type="mesh" mesh="J_Bip_R_UpperLeg"/>
                <geom type="sphere" size="0.05" mass="0.5" contype="0" conaffinity="0" rgba="0 0 0 0"/>
                <body name="J_Bip_R_LowerLeg" pos="0.000000 -0.364862 -0.000001">
                    <joint name="J_Bip_R_LowerLeg" type="ball"/>
                    <geom type="mesh" mesh="J_Bip_R_LowerLeg"/>
                    <geom type="sphere" size="0.05" mass="0.5" contype="0" conaffinity="0" rgba="0 0 0 0"/>
                    <body name="J_Bip_R_Foot" pos="0.000111 -0.409190 0.002444">
                        <joint name="J_Bip_R_Foot" type="ball"/>
                        <geom type="mesh" mesh="J_Bip_R_Foot"/>
                        <geom type="sphere" size="0.05" mass="0.5" contype="0" conaffinity="0" rgba="0 0 0 0"/>
                        <body name="J_Bip_R_ToeBase" pos="0.000000 -0.053395 0.094937">
                            <joint name="J_Bip_R_ToeBase" type="ball"/>
                            <geom type="mesh" mesh="J_Bip_R_ToeBase"/>
                            <geom type="sphere" size="0.05" mass="0.5" contype="0" conaffinity="0" rgba="0 0 0 0"/>
                        </body>
                    </body>
                </body>
            </body>
        </body>
    </worldbody>
</mujoco>